{"ray": {"sid": "704b271f8fdc4f0c99f4567136b902d3", "uid": null, "qid": "c832cad4cc4a41e4babd62928072931f", "rid": null, "bars": {"default": {"percent": "100", "remaining": "0"}}, "messages": [{"type": "ERROR", "content": "process - failed executing: [c832cad4cc4a41e4babd62928072931f]\nTraceback (most recent call last):\n  File \"C:\\Users\\avina\\AppData\\Local\\Packages\\PythonSoftwareFoundation.Python.3.11_qbz5n2kfra8p0\\LocalCache\\local-packages\\Python311\\site-packages\\openfabric_pysdk\\app\\worker.py\", line 90, in process\n    output = execution_callback_function(data, ray, self.state)\n             ^^^^^^^^^^^^^^^^^^^^^^^^^^^^^^^^^^^^^^^^^^^^^^^^^^\n  File \"C:\\Users\\avina\\Downloads\\openfabric-ai-software-engineer 2\\openfabric-ai-software-engineer\\main.py\", line 228, in execute\n    response = agent_executor.run({\"input\": text})\n               ^^^^^^^^^^^^^^^^^^^^^^^^^^^^^^^^^^^\n  File \"C:\\Users\\avina\\AppData\\Local\\Packages\\PythonSoftwareFoundation.Python.3.11_qbz5n2kfra8p0\\LocalCache\\local-packages\\Python311\\site-packages\\langchain\\chains\\base.py\", line 507, in run\n    return self(args[0], callbacks=callbacks, tags=tags, metadata=metadata)[\n           ^^^^^^^^^^^^^^^^^^^^^^^^^^^^^^^^^^^^^^^^^^^^^^^^^^^^^^^^^^^^^^^^\n  File \"C:\\Users\\avina\\AppData\\Local\\Packages\\PythonSoftwareFoundation.Python.3.11_qbz5n2kfra8p0\\LocalCache\\local-packages\\Python311\\site-packages\\langchain\\chains\\base.py\", line 312, in __call__\n    raise e\n  File \"C:\\Users\\avina\\AppData\\Local\\Packages\\PythonSoftwareFoundation.Python.3.11_qbz5n2kfra8p0\\LocalCache\\local-packages\\Python311\\site-packages\\langchain\\chains\\base.py\", line 306, in __call__\n    self._call(inputs, run_manager=run_manager)\n  File \"C:\\Users\\avina\\AppData\\Local\\Packages\\PythonSoftwareFoundation.Python.3.11_qbz5n2kfra8p0\\LocalCache\\local-packages\\Python311\\site-packages\\langchain\\agents\\agent.py\", line 1312, in _call\n    next_step_output = self._take_next_step(\n                       ^^^^^^^^^^^^^^^^^^^^^\n  File \"C:\\Users\\avina\\AppData\\Local\\Packages\\PythonSoftwareFoundation.Python.3.11_qbz5n2kfra8p0\\LocalCache\\local-packages\\Python311\\site-packages\\langchain\\agents\\agent.py\", line 1038, in _take_next_step\n    [\n  File \"C:\\Users\\avina\\AppData\\Local\\Packages\\PythonSoftwareFoundation.Python.3.11_qbz5n2kfra8p0\\LocalCache\\local-packages\\Python311\\site-packages\\langchain\\agents\\agent.py\", line 1038, in <listcomp>\n    [\n  File \"C:\\Users\\avina\\AppData\\Local\\Packages\\PythonSoftwareFoundation.Python.3.11_qbz5n2kfra8p0\\LocalCache\\local-packages\\Python311\\site-packages\\langchain\\agents\\agent.py\", line 1066, in _iter_next_step\n    output = self.agent.plan(\n             ^^^^^^^^^^^^^^^^\n  File \"C:\\Users\\avina\\AppData\\Local\\Packages\\PythonSoftwareFoundation.Python.3.11_qbz5n2kfra8p0\\LocalCache\\local-packages\\Python311\\site-packages\\langchain\\agents\\agent.py\", line 636, in plan\n    return self.output_parser.parse(full_output)\n           ^^^^^^^^^^^^^^^^^^^^^^^^^^^^^^^^^^^^^\n  File \"C:\\Users\\avina\\AppData\\Local\\Packages\\PythonSoftwareFoundation.Python.3.11_qbz5n2kfra8p0\\LocalCache\\local-packages\\Python311\\site-packages\\langchain\\agents\\mrkl\\output_parser.py\", line 39, in parse\n    logging.warning(f'{action_match} XYYYYYYYYYY')\n                       ^^^^^^^^^^^^\nUnboundLocalError: cannot access local variable 'action_match' where it is not associated with a value\n", "created_at": "2023-12-30T14:36:11.313792"}], "status": "FAILED", "created_at": "2023-12-30T14:36:08.599559", "updated_at": "2023-12-30T14:36:11.313792", "finished": true}, "in": {"text": ["string"]}, "out": {}}